---
title: "pg_wsl"
output: html_document
---

```{r setup, include=FALSE}
knitr::opts_chunk$set(echo = TRUE)
```

## 

`wsl` installed.  `postgres` installed into `wsl` .  Manged now to get bcdata bc2pg bc-airports --db_url postgresql://postgres:postgres@localhost:5432/postgis to run in my command line but not without the db_url option and still cannot for the life of me figure out how to get `bcdata` to burn anything to the db in wsl. Failed. Another 24.25hours invested.  Insane.  Here is a bit of a file tracking what I have been trying.



I have so far set up wsl and have installed a postgresql 13 using https://computingforgeeks.com/how-to-install-postgresql-13-on-ubuntu/.

<br>


Only real mod to this was that I needed to assign a password `sudo passwd postgres` as per https://karansingh1559.medium.com/how-to-set-up-postgresql-on-ubuntu-for-wsl-fcbb777d165b 

<br>

I changed the port to 5434 as I already have postgres on 5432 in my normal windows OS so I will leave there. I changed it as per 
https://karansingh1559.medium.com/how-to-set-up-postgresql-on-ubuntu-for-wsl-fcbb777d165b with `sudo vi /etc/postgresql/13/main/postgresql.conf`.

`sudo /etc/init.d/postgresql stop`
`sudo /etc/init.d/postgresql start`

<br>

Bit of info here on changing unix socket https://www.jamescoyle.net/how-to/3019-how-to-change-the-listening-port-for-postgresql-database#:~:text=The%20default%20TCP%20port%20for,file%20for%20the%20database%20server.

<br>

`sudo vi /etc/postgresql/13/main/postgresql.conf`
listen_addresses = '*'                  # what IP address(es) to listen on;  



<br>

To insert in Vim press I. To get out press `:` then tyupe `q!` 
to save and leave `:wq!`
https://help.dreamhost.com/hc/en-us/articles/115006413028-Creating-and-editing-a-file-via-SSH#:~:text=Using%20'vim'%20to%20create%20and%20edit%20a%20file,-Log%20into%20your&text=Navigate%20to%20the%20directory%20location%20you%20wish%20to%20create%20the,or%20edit%20an%20existing%20file.&text=Press%20the%20letter%20i%20on,enter%20INSERT%20mode%20in%20vim.&text=Start%20typing%20into%20the%20file,file%2C%20press%20the%20ESC%20key.


<br>
I didn't add postgis at install so will try to add it now with https://computingforgeeks.com/how-to-install-postgis-on-ubuntu-debian/

`psql -d postgis_test`
`CREATE EXTENSION postgis;`
verify:

`SELECT PostGIS_version();`

success

`sudo -i -u postgres`

Seems to be working.  

Lets try to run bcdata and set up env variables

`(base) newgraph@MSI:~$ bcdata list | grep AIRPORTS
WHSE_IMAGERY_AND_BASE_MAPS.GSR_AIRPORTS_SVW`

works



(base) newgraph@MSI:~$ bcdata list | grep AIRPORTS
WHSE_IMAGERY_AND_BASE_MAPS.GSR_AIRPORTS_SVW
(base) newgraph@MSI:~$ bcdata bc2pg bc-airports --db_url postgresql://postgres:postgres@host:5434/postgis_test
Traceback (most recent call last):
  File "/home/newgraph/miniconda3/lib/python3.8/site-packages/sqlalchemy/engine/base.py", line 2336, in _wrap_pool_connect
    return fn()
  File "/home/newgraph/miniconda3/lib/python3.8/site-packages/sqlalchemy/pool/base.py", line 364, in connect
    return _ConnectionFairy._checkout(self)
  File "/home/newgraph/miniconda3/lib/python3.8/site-packages/sqlalchemy/pool/base.py", line 778, in _checkout
    fairy = _ConnectionRecord.checkout(pool)
  File "/home/newgraph/miniconda3/lib/python3.8/site-packages/sqlalchemy/pool/base.py", line 495, in checkout
    rec = pool._do_get()
  File "/home/newgraph/miniconda3/lib/python3.8/site-packages/sqlalchemy/pool/impl.py", line 140, in _do_get
    self._dec_overflow()
  File "/home/newgraph/miniconda3/lib/python3.8/site-packages/sqlalchemy/util/langhelpers.py", line 68, in __exit__
    compat.raise_(
  File "/home/newgraph/miniconda3/lib/python3.8/site-packages/sqlalchemy/util/compat.py", line 182, in raise_
    raise exception
  File "/home/newgraph/miniconda3/lib/python3.8/site-packages/sqlalchemy/pool/impl.py", line 137, in _do_get
    return self._create_connection()
  File "/home/newgraph/miniconda3/lib/python3.8/site-packages/sqlalchemy/pool/base.py", line 309, in _create_connection
    return _ConnectionRecord(self)
  File "/home/newgraph/miniconda3/lib/python3.8/site-packages/sqlalchemy/pool/base.py", line 440, in __init__
    self.__connect(first_connect_check=True)
  File "/home/newgraph/miniconda3/lib/python3.8/site-packages/sqlalchemy/pool/base.py", line 661, in __connect
    pool.logger.debug("Error on connect(): %s", e)
  File "/home/newgraph/miniconda3/lib/python3.8/site-packages/sqlalchemy/util/langhelpers.py", line 68, in __exit__
    compat.raise_(
  File "/home/newgraph/miniconda3/lib/python3.8/site-packages/sqlalchemy/util/compat.py", line 182, in raise_
    raise exception
  File "/home/newgraph/miniconda3/lib/python3.8/site-packages/sqlalchemy/pool/base.py", line 656, in __connect
    connection = pool._invoke_creator(self)
  File "/home/newgraph/miniconda3/lib/python3.8/site-packages/sqlalchemy/engine/strategies.py", line 114, in connect
    return dialect.connect(*cargs, **cparams)
  File "/home/newgraph/miniconda3/lib/python3.8/site-packages/sqlalchemy/engine/default.py", line 508, in connect
    return self.dbapi.connect(*cargs, **cparams)
  File "/home/newgraph/miniconda3/lib/python3.8/site-packages/psycopg2/__init__.py", line 127, in connect
    conn = _connect(dsn, connection_factory=connection_factory, **kwasync)
psycopg2.OperationalError: could not connect to server: Connection timed out
        Is the server running on host "host" (172.18.144.1) and accepting
        TCP/IP connections on port 5434?


The above exception was the direct cause of the following exception:

Traceback (most recent call last):
  File "/home/newgraph/miniconda3/bin/bcdata", line 8, in <module>
    sys.exit(cli())
  File "/home/newgraph/miniconda3/lib/python3.8/site-packages/click/core.py", line 829, in __call__
    return self.main(*args, **kwargs)
  File "/home/newgraph/miniconda3/lib/python3.8/site-packages/click/core.py", line 782, in main
    rv = self.invoke(ctx)
  File "/home/newgraph/miniconda3/lib/python3.8/site-packages/click/core.py", line 1259, in invoke
    return _process_result(sub_ctx.command.invoke(sub_ctx))
  File "/home/newgraph/miniconda3/lib/python3.8/site-packages/click/core.py", line 1066, in invoke
    return ctx.invoke(self.callback, **ctx.params)
  File "/home/newgraph/miniconda3/lib/python3.8/site-packages/click/core.py", line 610, in invoke
    return callback(*args, **kwargs)
  File "/home/newgraph/miniconda3/lib/python3.8/site-packages/bcdata/cli.py", line 351, in bc2pg
    if schema not in conn.schemas:
  File "/home/newgraph/miniconda3/lib/python3.8/site-packages/pgdata/database.py", line 54, in schemas
    schemas = self.query(sql).fetchall()
  File "/home/newgraph/miniconda3/lib/python3.8/site-packages/pgdata/database.py", line 167, in query
    return self.engine.execute(sql, params)
  File "/home/newgraph/miniconda3/lib/python3.8/site-packages/sqlalchemy/engine/base.py", line 2234, in execute
    connection = self._contextual_connect(close_with_result=True)
  File "/home/newgraph/miniconda3/lib/python3.8/site-packages/sqlalchemy/engine/base.py", line 2302, in _contextual_connect
    self._wrap_pool_connect(self.pool.connect, None),
  File "/home/newgraph/miniconda3/lib/python3.8/site-packages/sqlalchemy/engine/base.py", line 2339, in _wrap_pool_connect
    Connection._handle_dbapi_exception_noconnection(
  File "/home/newgraph/miniconda3/lib/python3.8/site-packages/sqlalchemy/engine/base.py", line 1583, in _handle_dbapi_exception_noconnection
    util.raise_(
  File "/home/newgraph/miniconda3/lib/python3.8/site-packages/sqlalchemy/util/compat.py", line 182, in raise_
    raise exception
  File "/home/newgraph/miniconda3/lib/python3.8/site-packages/sqlalchemy/engine/base.py", line 2336, in _wrap_pool_connect
    return fn()
  File "/home/newgraph/miniconda3/lib/python3.8/site-packages/sqlalchemy/pool/base.py", line 364, in connect
    return _ConnectionFairy._checkout(self)
  File "/home/newgraph/miniconda3/lib/python3.8/site-packages/sqlalchemy/pool/base.py", line 778, in _checkout
    fairy = _ConnectionRecord.checkout(pool)
  File "/home/newgraph/miniconda3/lib/python3.8/site-packages/sqlalchemy/pool/base.py", line 495, in checkout
    rec = pool._do_get()
  File "/home/newgraph/miniconda3/lib/python3.8/site-packages/sqlalchemy/pool/impl.py", line 140, in _do_get
    self._dec_overflow()
  File "/home/newgraph/miniconda3/lib/python3.8/site-packages/sqlalchemy/util/langhelpers.py", line 68, in __exit__
    compat.raise_(
  File "/home/newgraph/miniconda3/lib/python3.8/site-packages/sqlalchemy/util/compat.py", line 182, in raise_
    raise exception
  File "/home/newgraph/miniconda3/lib/python3.8/site-packages/sqlalchemy/pool/impl.py", line 137, in _do_get
    return self._create_connection()
  File "/home/newgraph/miniconda3/lib/python3.8/site-packages/sqlalchemy/pool/base.py", line 309, in _create_connection
    return _ConnectionRecord(self)
  File "/home/newgraph/miniconda3/lib/python3.8/site-packages/sqlalchemy/pool/base.py", line 440, in __init__
    self.__connect(first_connect_check=True)
  File "/home/newgraph/miniconda3/lib/python3.8/site-packages/sqlalchemy/pool/base.py", line 661, in __connect
    pool.logger.debug("Error on connect(): %s", e)
  File "/home/newgraph/miniconda3/lib/python3.8/site-packages/sqlalchemy/util/langhelpers.py", line 68, in __exit__
    compat.raise_(
  File "/home/newgraph/miniconda3/lib/python3.8/site-packages/sqlalchemy/util/compat.py", line 182, in raise_
    raise exception
  File "/home/newgraph/miniconda3/lib/python3.8/site-packages/sqlalchemy/pool/base.py", line 656, in __connect
    connection = pool._invoke_creator(self)
  File "/home/newgraph/miniconda3/lib/python3.8/site-packages/sqlalchemy/engine/strategies.py", line 114, in connect
    return dialect.connect(*cargs, **cparams)
  File "/home/newgraph/miniconda3/lib/python3.8/site-packages/sqlalchemy/engine/default.py", line 508, in connect
    return self.dbapi.connect(*cargs, **cparams)
  File "/home/newgraph/miniconda3/lib/python3.8/site-packages/psycopg2/__init__.py", line 127, in connect
    conn = _connect(dsn, connection_factory=connection_factory, **kwasync)
sqlalchemy.exc.OperationalError: (psycopg2.OperationalError) could not connect to server: Connection timed out
        Is the server running on host "host" (172.18.144.1) and accepting
        TCP/IP connections on port 5434?

(Background on this error at: http://sqlalche.me/e/13/e3q8)
(base) newgraph@MSI:~$ psql --host = 172.18.144.1 --port=5434 --user=postgres
psql: error: could not translate host name "=" to address: Name or service not known
(base) newgraph@MSI:~$ psql --host=172.18.144.1 --port=5434 --user=postgres
psql: error: could not connect to server: Connection timed out
        Is the server running on host "172.18.144.1" and accepting
        TCP/IP connections on port 5434?
(base) newgraph@MSI:~$ sudo su - postgres
postgres@MSI:~$ psql
psql (13.2 (Ubuntu 13.2-1.pgdg18.04+1))
Type "help" for help.

postgres=# \ls
invalid command \ls
Try \? for help.
postgres=# \l
                               List of databases
     Name     |  Owner   | Encoding | Collate |  Ctype  |   Access privileges
--------------+----------+----------+---------+---------+-----------------------
 postgis_test | postgres | UTF8     | C.UTF-8 | C.UTF-8 | =Tc/postgres         +
              |          |          |         |         | postgres=CTc/postgres+
              |          |          |         |         | newgraph=CTc/postgres
 postgres     | postgres | UTF8     | C.UTF-8 | C.UTF-8 |
 template0    | postgres | UTF8     | C.UTF-8 | C.UTF-8 | =c/postgres          +
              |          |          |         |         | postgres=CTc/postgres
 template1    | postgres | UTF8     | C.UTF-8 | C.UTF-8 | =c/postgres          +
              |          |          |         |         | postgres=CTc/postgres
(4 rows)

postgres=# q
postgres-# \q
postgres@MSI:~$ exit
logout
(base) newgraph@MSI:~$ bcdata bc2pg bc-airports --db_url postgresql://postgres:postgres@localhost:5434/postgis_test
Traceback (most recent call last):
  File "/home/newgraph/miniconda3/lib/python3.8/site-packages/sqlalchemy/engine/base.py", line 2336, in _wrap_pool_connect
    return fn()
  File "/home/newgraph/miniconda3/lib/python3.8/site-packages/sqlalchemy/pool/base.py", line 364, in connect
    return _ConnectionFairy._checkout(self)
  File "/home/newgraph/miniconda3/lib/python3.8/site-packages/sqlalchemy/pool/base.py", line 778, in _checkout
    fairy = _ConnectionRecord.checkout(pool)
  File "/home/newgraph/miniconda3/lib/python3.8/site-packages/sqlalchemy/pool/base.py", line 495, in checkout
    rec = pool._do_get()
  File "/home/newgraph/miniconda3/lib/python3.8/site-packages/sqlalchemy/pool/impl.py", line 140, in _do_get
    self._dec_overflow()
  File "/home/newgraph/miniconda3/lib/python3.8/site-packages/sqlalchemy/util/langhelpers.py", line 68, in __exit__
    compat.raise_(
  File "/home/newgraph/miniconda3/lib/python3.8/site-packages/sqlalchemy/util/compat.py", line 182, in raise_
    raise exception
  File "/home/newgraph/miniconda3/lib/python3.8/site-packages/sqlalchemy/pool/impl.py", line 137, in _do_get
    return self._create_connection()
  File "/home/newgraph/miniconda3/lib/python3.8/site-packages/sqlalchemy/pool/base.py", line 309, in _create_connection
    return _ConnectionRecord(self)
  File "/home/newgraph/miniconda3/lib/python3.8/site-packages/sqlalchemy/pool/base.py", line 440, in __init__
    self.__connect(first_connect_check=True)
  File "/home/newgraph/miniconda3/lib/python3.8/site-packages/sqlalchemy/pool/base.py", line 661, in __connect
    pool.logger.debug("Error on connect(): %s", e)
  File "/home/newgraph/miniconda3/lib/python3.8/site-packages/sqlalchemy/util/langhelpers.py", line 68, in __exit__
    compat.raise_(
  File "/home/newgraph/miniconda3/lib/python3.8/site-packages/sqlalchemy/util/compat.py", line 182, in raise_
    raise exception
  File "/home/newgraph/miniconda3/lib/python3.8/site-packages/sqlalchemy/pool/base.py", line 656, in __connect
    connection = pool._invoke_creator(self)
  File "/home/newgraph/miniconda3/lib/python3.8/site-packages/sqlalchemy/engine/strategies.py", line 114, in connect
    return dialect.connect(*cargs, **cparams)
  File "/home/newgraph/miniconda3/lib/python3.8/site-packages/sqlalchemy/engine/default.py", line 508, in connect
    return self.dbapi.connect(*cargs, **cparams)
  File "/home/newgraph/miniconda3/lib/python3.8/site-packages/psycopg2/__init__.py", line 127, in connect
    conn = _connect(dsn, connection_factory=connection_factory, **kwasync)
psycopg2.OperationalError: FATAL:  password authentication failed for user "postgres"
FATAL:  password authentication failed for user "postgres"


The above exception was the direct cause of the following exception:

Traceback (most recent call last):
  File "/home/newgraph/miniconda3/bin/bcdata", line 8, in <module>
    sys.exit(cli())
  File "/home/newgraph/miniconda3/lib/python3.8/site-packages/click/core.py", line 829, in __call__
    return self.main(*args, **kwargs)
  File "/home/newgraph/miniconda3/lib/python3.8/site-packages/click/core.py", line 782, in main
    rv = self.invoke(ctx)
  File "/home/newgraph/miniconda3/lib/python3.8/site-packages/click/core.py", line 1259, in invoke
    return _process_result(sub_ctx.command.invoke(sub_ctx))
  File "/home/newgraph/miniconda3/lib/python3.8/site-packages/click/core.py", line 1066, in invoke
    return ctx.invoke(self.callback, **ctx.params)
  File "/home/newgraph/miniconda3/lib/python3.8/site-packages/click/core.py", line 610, in invoke
    return callback(*args, **kwargs)
  File "/home/newgraph/miniconda3/lib/python3.8/site-packages/bcdata/cli.py", line 351, in bc2pg
    if schema not in conn.schemas:
  File "/home/newgraph/miniconda3/lib/python3.8/site-packages/pgdata/database.py", line 54, in schemas
    schemas = self.query(sql).fetchall()
  File "/home/newgraph/miniconda3/lib/python3.8/site-packages/pgdata/database.py", line 167, in query
    return self.engine.execute(sql, params)
  File "/home/newgraph/miniconda3/lib/python3.8/site-packages/sqlalchemy/engine/base.py", line 2234, in execute
    connection = self._contextual_connect(close_with_result=True)
  File "/home/newgraph/miniconda3/lib/python3.8/site-packages/sqlalchemy/engine/base.py", line 2302, in _contextual_connect
    self._wrap_pool_connect(self.pool.connect, None),
  File "/home/newgraph/miniconda3/lib/python3.8/site-packages/sqlalchemy/engine/base.py", line 2339, in _wrap_pool_connect
    Connection._handle_dbapi_exception_noconnection(
  File "/home/newgraph/miniconda3/lib/python3.8/site-packages/sqlalchemy/engine/base.py", line 1583, in _handle_dbapi_exception_noconnection
    util.raise_(
  File "/home/newgraph/miniconda3/lib/python3.8/site-packages/sqlalchemy/util/compat.py", line 182, in raise_
    raise exception
  File "/home/newgraph/miniconda3/lib/python3.8/site-packages/sqlalchemy/engine/base.py", line 2336, in _wrap_pool_connect
    return fn()
  File "/home/newgraph/miniconda3/lib/python3.8/site-packages/sqlalchemy/pool/base.py", line 364, in connect
    return _ConnectionFairy._checkout(self)
  File "/home/newgraph/miniconda3/lib/python3.8/site-packages/sqlalchemy/pool/base.py", line 778, in _checkout
    fairy = _ConnectionRecord.checkout(pool)
  File "/home/newgraph/miniconda3/lib/python3.8/site-packages/sqlalchemy/pool/base.py", line 495, in checkout
    rec = pool._do_get()
  File "/home/newgraph/miniconda3/lib/python3.8/site-packages/sqlalchemy/pool/impl.py", line 140, in _do_get
    self._dec_overflow()
  File "/home/newgraph/miniconda3/lib/python3.8/site-packages/sqlalchemy/util/langhelpers.py", line 68, in __exit__
    compat.raise_(
  File "/home/newgraph/miniconda3/lib/python3.8/site-packages/sqlalchemy/util/compat.py", line 182, in raise_
    raise exception
  File "/home/newgraph/miniconda3/lib/python3.8/site-packages/sqlalchemy/pool/impl.py", line 137, in _do_get
    return self._create_connection()
  File "/home/newgraph/miniconda3/lib/python3.8/site-packages/sqlalchemy/pool/base.py", line 309, in _create_connection
    return _ConnectionRecord(self)
  File "/home/newgraph/miniconda3/lib/python3.8/site-packages/sqlalchemy/pool/base.py", line 440, in __init__
    self.__connect(first_connect_check=True)
  File "/home/newgraph/miniconda3/lib/python3.8/site-packages/sqlalchemy/pool/base.py", line 661, in __connect
    pool.logger.debug("Error on connect(): %s", e)
  File "/home/newgraph/miniconda3/lib/python3.8/site-packages/sqlalchemy/util/langhelpers.py", line 68, in __exit__
    compat.raise_(
  File "/home/newgraph/miniconda3/lib/python3.8/site-packages/sqlalchemy/util/compat.py", line 182, in raise_
    raise exception
  File "/home/newgraph/miniconda3/lib/python3.8/site-packages/sqlalchemy/pool/base.py", line 656, in __connect
    connection = pool._invoke_creator(self)
  File "/home/newgraph/miniconda3/lib/python3.8/site-packages/sqlalchemy/engine/strategies.py", line 114, in connect
    return dialect.connect(*cargs, **cparams)
  File "/home/newgraph/miniconda3/lib/python3.8/site-packages/sqlalchemy/engine/default.py", line 508, in connect
    return self.dbapi.connect(*cargs, **cparams)
  File "/home/newgraph/miniconda3/lib/python3.8/site-packages/psycopg2/__init__.py", line 127, in connect
    conn = _connect(dsn, connection_factory=connection_factory, **kwasync)
sqlalchemy.exc.OperationalError: (psycopg2.OperationalError) FATAL:  password authentication failed for user "postgres"
FATAL:  password authentication failed for user "postgres"

(Background on this error at: http://sqlalche.me/e/13/e3q8)
(base) newgraph@MSI:~$ sudo -i -u postgres
postgres@MSI:~$ bcdata bc2pg bc-airports --db_url postgresql://postgres:postgres@localhost:5434/postgis_test
bcdata: command not found
postgres@MSI:~$ exit
logout
(base) newgraph@MSI:~$ bcdata bc2pg bc-airports --db_url postgresql://newgraph:postgres@localhost:5434/postgis_test
Traceback (most recent call last):
  File "/home/newgraph/miniconda3/lib/python3.8/site-packages/sqlalchemy/engine/base.py", line 2336, in _wrap_pool_connect
    return fn()
  File "/home/newgraph/miniconda3/lib/python3.8/site-packages/sqlalchemy/pool/base.py", line 364, in connect
    return _ConnectionFairy._checkout(self)
  File "/home/newgraph/miniconda3/lib/python3.8/site-packages/sqlalchemy/pool/base.py", line 778, in _checkout
    fairy = _ConnectionRecord.checkout(pool)
  File "/home/newgraph/miniconda3/lib/python3.8/site-packages/sqlalchemy/pool/base.py", line 495, in checkout
    rec = pool._do_get()
  File "/home/newgraph/miniconda3/lib/python3.8/site-packages/sqlalchemy/pool/impl.py", line 140, in _do_get
    self._dec_overflow()
  File "/home/newgraph/miniconda3/lib/python3.8/site-packages/sqlalchemy/util/langhelpers.py", line 68, in __exit__
    compat.raise_(
  File "/home/newgraph/miniconda3/lib/python3.8/site-packages/sqlalchemy/util/compat.py", line 182, in raise_
    raise exception
  File "/home/newgraph/miniconda3/lib/python3.8/site-packages/sqlalchemy/pool/impl.py", line 137, in _do_get
    return self._create_connection()
  File "/home/newgraph/miniconda3/lib/python3.8/site-packages/sqlalchemy/pool/base.py", line 309, in _create_connection
    return _ConnectionRecord(self)
  File "/home/newgraph/miniconda3/lib/python3.8/site-packages/sqlalchemy/pool/base.py", line 440, in __init__
    self.__connect(first_connect_check=True)
  File "/home/newgraph/miniconda3/lib/python3.8/site-packages/sqlalchemy/pool/base.py", line 661, in __connect
    pool.logger.debug("Error on connect(): %s", e)
  File "/home/newgraph/miniconda3/lib/python3.8/site-packages/sqlalchemy/util/langhelpers.py", line 68, in __exit__
    compat.raise_(
  File "/home/newgraph/miniconda3/lib/python3.8/site-packages/sqlalchemy/util/compat.py", line 182, in raise_
    raise exception
  File "/home/newgraph/miniconda3/lib/python3.8/site-packages/sqlalchemy/pool/base.py", line 656, in __connect
    connection = pool._invoke_creator(self)
  File "/home/newgraph/miniconda3/lib/python3.8/site-packages/sqlalchemy/engine/strategies.py", line 114, in connect
    return dialect.connect(*cargs, **cparams)
  File "/home/newgraph/miniconda3/lib/python3.8/site-packages/sqlalchemy/engine/default.py", line 508, in connect
    return self.dbapi.connect(*cargs, **cparams)
  File "/home/newgraph/miniconda3/lib/python3.8/site-packages/psycopg2/__init__.py", line 127, in connect
    conn = _connect(dsn, connection_factory=connection_factory, **kwasync)
psycopg2.OperationalError: FATAL:  password authentication failed for user "newgraph"
FATAL:  password authentication failed for user "newgraph"


The above exception was the direct cause of the following exception:

Traceback (most recent call last):
  File "/home/newgraph/miniconda3/bin/bcdata", line 8, in <module>
    sys.exit(cli())
  File "/home/newgraph/miniconda3/lib/python3.8/site-packages/click/core.py", line 829, in __call__
    return self.main(*args, **kwargs)
  File "/home/newgraph/miniconda3/lib/python3.8/site-packages/click/core.py", line 782, in main
    rv = self.invoke(ctx)
  File "/home/newgraph/miniconda3/lib/python3.8/site-packages/click/core.py", line 1259, in invoke
    return _process_result(sub_ctx.command.invoke(sub_ctx))
  File "/home/newgraph/miniconda3/lib/python3.8/site-packages/click/core.py", line 1066, in invoke
    return ctx.invoke(self.callback, **ctx.params)
  File "/home/newgraph/miniconda3/lib/python3.8/site-packages/click/core.py", line 610, in invoke
    return callback(*args, **kwargs)
  File "/home/newgraph/miniconda3/lib/python3.8/site-packages/bcdata/cli.py", line 351, in bc2pg
    if schema not in conn.schemas:
  File "/home/newgraph/miniconda3/lib/python3.8/site-packages/pgdata/database.py", line 54, in schemas
    schemas = self.query(sql).fetchall()
  File "/home/newgraph/miniconda3/lib/python3.8/site-packages/pgdata/database.py", line 167, in query
    return self.engine.execute(sql, params)
  File "/home/newgraph/miniconda3/lib/python3.8/site-packages/sqlalchemy/engine/base.py", line 2234, in execute
    connection = self._contextual_connect(close_with_result=True)
  File "/home/newgraph/miniconda3/lib/python3.8/site-packages/sqlalchemy/engine/base.py", line 2302, in _contextual_connect
    self._wrap_pool_connect(self.pool.connect, None),
  File "/home/newgraph/miniconda3/lib/python3.8/site-packages/sqlalchemy/engine/base.py", line 2339, in _wrap_pool_connect
    Connection._handle_dbapi_exception_noconnection(
  File "/home/newgraph/miniconda3/lib/python3.8/site-packages/sqlalchemy/engine/base.py", line 1583, in _handle_dbapi_exception_noconnection
    util.raise_(
  File "/home/newgraph/miniconda3/lib/python3.8/site-packages/sqlalchemy/util/compat.py", line 182, in raise_
    raise exception
  File "/home/newgraph/miniconda3/lib/python3.8/site-packages/sqlalchemy/engine/base.py", line 2336, in _wrap_pool_connect
    return fn()
  File "/home/newgraph/miniconda3/lib/python3.8/site-packages/sqlalchemy/pool/base.py", line 364, in connect
    return _ConnectionFairy._checkout(self)
  File "/home/newgraph/miniconda3/lib/python3.8/site-packages/sqlalchemy/pool/base.py", line 778, in _checkout
    fairy = _ConnectionRecord.checkout(pool)
  File "/home/newgraph/miniconda3/lib/python3.8/site-packages/sqlalchemy/pool/base.py", line 495, in checkout
    rec = pool._do_get()
  File "/home/newgraph/miniconda3/lib/python3.8/site-packages/sqlalchemy/pool/impl.py", line 140, in _do_get
    self._dec_overflow()
  File "/home/newgraph/miniconda3/lib/python3.8/site-packages/sqlalchemy/util/langhelpers.py", line 68, in __exit__
    compat.raise_(
  File "/home/newgraph/miniconda3/lib/python3.8/site-packages/sqlalchemy/util/compat.py", line 182, in raise_
    raise exception
  File "/home/newgraph/miniconda3/lib/python3.8/site-packages/sqlalchemy/pool/impl.py", line 137, in _do_get
    return self._create_connection()
  File "/home/newgraph/miniconda3/lib/python3.8/site-packages/sqlalchemy/pool/base.py", line 309, in _create_connection
    return _ConnectionRecord(self)
  File "/home/newgraph/miniconda3/lib/python3.8/site-packages/sqlalchemy/pool/base.py", line 440, in __init__
    self.__connect(first_connect_check=True)
  File "/home/newgraph/miniconda3/lib/python3.8/site-packages/sqlalchemy/pool/base.py", line 661, in __connect
    pool.logger.debug("Error on connect(): %s", e)
  File "/home/newgraph/miniconda3/lib/python3.8/site-packages/sqlalchemy/util/langhelpers.py", line 68, in __exit__
    compat.raise_(
  File "/home/newgraph/miniconda3/lib/python3.8/site-packages/sqlalchemy/util/compat.py", line 182, in raise_
    raise exception
  File "/home/newgraph/miniconda3/lib/python3.8/site-packages/sqlalchemy/pool/base.py", line 656, in __connect
    connection = pool._invoke_creator(self)
  File "/home/newgraph/miniconda3/lib/python3.8/site-packages/sqlalchemy/engine/strategies.py", line 114, in connect
    return dialect.connect(*cargs, **cparams)
  File "/home/newgraph/miniconda3/lib/python3.8/site-packages/sqlalchemy/engine/default.py", line 508, in connect
    return self.dbapi.connect(*cargs, **cparams)
  File "/home/newgraph/miniconda3/lib/python3.8/site-packages/psycopg2/__init__.py", line 127, in connect
    conn = _connect(dsn, connection_factory=connection_factory, **kwasync)
sqlalchemy.exc.OperationalError: (psycopg2.OperationalError) FATAL:  password authentication failed for user "newgraph"
FATAL:  password authentication failed for user "newgraph"

(Background on this error at: http://sqlalche.me/e/13/e3q8)
(base) newgraph@MSI:~$ bcdata bc2pg bc-airports --db_url postgresql://newgraph:newgraph101@localhost:5434/postgis_test
Traceback (most recent call last):
  File "/home/newgraph/miniconda3/lib/python3.8/site-packages/sqlalchemy/engine/base.py", line 2336, in _wrap_pool_connect
    return fn()
  File "/home/newgraph/miniconda3/lib/python3.8/site-packages/sqlalchemy/pool/base.py", line 364, in connect
    return _ConnectionFairy._checkout(self)
  File "/home/newgraph/miniconda3/lib/python3.8/site-packages/sqlalchemy/pool/base.py", line 778, in _checkout
    fairy = _ConnectionRecord.checkout(pool)
  File "/home/newgraph/miniconda3/lib/python3.8/site-packages/sqlalchemy/pool/base.py", line 495, in checkout
    rec = pool._do_get()
  File "/home/newgraph/miniconda3/lib/python3.8/site-packages/sqlalchemy/pool/impl.py", line 140, in _do_get
    self._dec_overflow()
  File "/home/newgraph/miniconda3/lib/python3.8/site-packages/sqlalchemy/util/langhelpers.py", line 68, in __exit__
    compat.raise_(
  File "/home/newgraph/miniconda3/lib/python3.8/site-packages/sqlalchemy/util/compat.py", line 182, in raise_
    raise exception
  File "/home/newgraph/miniconda3/lib/python3.8/site-packages/sqlalchemy/pool/impl.py", line 137, in _do_get
    return self._create_connection()
  File "/home/newgraph/miniconda3/lib/python3.8/site-packages/sqlalchemy/pool/base.py", line 309, in _create_connection
    return _ConnectionRecord(self)
  File "/home/newgraph/miniconda3/lib/python3.8/site-packages/sqlalchemy/pool/base.py", line 440, in __init__
    self.__connect(first_connect_check=True)
  File "/home/newgraph/miniconda3/lib/python3.8/site-packages/sqlalchemy/pool/base.py", line 661, in __connect
    pool.logger.debug("Error on connect(): %s", e)
  File "/home/newgraph/miniconda3/lib/python3.8/site-packages/sqlalchemy/util/langhelpers.py", line 68, in __exit__
    compat.raise_(
  File "/home/newgraph/miniconda3/lib/python3.8/site-packages/sqlalchemy/util/compat.py", line 182, in raise_
    raise exception
  File "/home/newgraph/miniconda3/lib/python3.8/site-packages/sqlalchemy/pool/base.py", line 656, in __connect
    connection = pool._invoke_creator(self)
  File "/home/newgraph/miniconda3/lib/python3.8/site-packages/sqlalchemy/engine/strategies.py", line 114, in connect
    return dialect.connect(*cargs, **cparams)
  File "/home/newgraph/miniconda3/lib/python3.8/site-packages/sqlalchemy/engine/default.py", line 508, in connect
    return self.dbapi.connect(*cargs, **cparams)
  File "/home/newgraph/miniconda3/lib/python3.8/site-packages/psycopg2/__init__.py", line 127, in connect
    conn = _connect(dsn, connection_factory=connection_factory, **kwasync)
psycopg2.OperationalError: FATAL:  password authentication failed for user "newgraph"
FATAL:  password authentication failed for user "newgraph"


The above exception was the direct cause of the following exception:

Traceback (most recent call last):
  File "/home/newgraph/miniconda3/bin/bcdata", line 8, in <module>
    sys.exit(cli())
  File "/home/newgraph/miniconda3/lib/python3.8/site-packages/click/core.py", line 829, in __call__
    return self.main(*args, **kwargs)
  File "/home/newgraph/miniconda3/lib/python3.8/site-packages/click/core.py", line 782, in main
    rv = self.invoke(ctx)
  File "/home/newgraph/miniconda3/lib/python3.8/site-packages/click/core.py", line 1259, in invoke
    return _process_result(sub_ctx.command.invoke(sub_ctx))
  File "/home/newgraph/miniconda3/lib/python3.8/site-packages/click/core.py", line 1066, in invoke
    return ctx.invoke(self.callback, **ctx.params)
  File "/home/newgraph/miniconda3/lib/python3.8/site-packages/click/core.py", line 610, in invoke
    return callback(*args, **kwargs)
  File "/home/newgraph/miniconda3/lib/python3.8/site-packages/bcdata/cli.py", line 351, in bc2pg
    if schema not in conn.schemas:
  File "/home/newgraph/miniconda3/lib/python3.8/site-packages/pgdata/database.py", line 54, in schemas
    schemas = self.query(sql).fetchall()
  File "/home/newgraph/miniconda3/lib/python3.8/site-packages/pgdata/database.py", line 167, in query
    return self.engine.execute(sql, params)
  File "/home/newgraph/miniconda3/lib/python3.8/site-packages/sqlalchemy/engine/base.py", line 2234, in execute
    connection = self._contextual_connect(close_with_result=True)
  File "/home/newgraph/miniconda3/lib/python3.8/site-packages/sqlalchemy/engine/base.py", line 2302, in _contextual_connect
    self._wrap_pool_connect(self.pool.connect, None),
  File "/home/newgraph/miniconda3/lib/python3.8/site-packages/sqlalchemy/engine/base.py", line 2339, in _wrap_pool_connect
    Connection._handle_dbapi_exception_noconnection(
  File "/home/newgraph/miniconda3/lib/python3.8/site-packages/sqlalchemy/engine/base.py", line 1583, in _handle_dbapi_exception_noconnection
    util.raise_(
  File "/home/newgraph/miniconda3/lib/python3.8/site-packages/sqlalchemy/util/compat.py", line 182, in raise_
    raise exception
  File "/home/newgraph/miniconda3/lib/python3.8/site-packages/sqlalchemy/engine/base.py", line 2336, in _wrap_pool_connect
    return fn()
  File "/home/newgraph/miniconda3/lib/python3.8/site-packages/sqlalchemy/pool/base.py", line 364, in connect
    return _ConnectionFairy._checkout(self)
  File "/home/newgraph/miniconda3/lib/python3.8/site-packages/sqlalchemy/pool/base.py", line 778, in _checkout
    fairy = _ConnectionRecord.checkout(pool)
  File "/home/newgraph/miniconda3/lib/python3.8/site-packages/sqlalchemy/pool/base.py", line 495, in checkout
    rec = pool._do_get()
  File "/home/newgraph/miniconda3/lib/python3.8/site-packages/sqlalchemy/pool/impl.py", line 140, in _do_get
    self._dec_overflow()
  File "/home/newgraph/miniconda3/lib/python3.8/site-packages/sqlalchemy/util/langhelpers.py", line 68, in __exit__
    compat.raise_(
  File "/home/newgraph/miniconda3/lib/python3.8/site-packages/sqlalchemy/util/compat.py", line 182, in raise_
    raise exception
  File "/home/newgraph/miniconda3/lib/python3.8/site-packages/sqlalchemy/pool/impl.py", line 137, in _do_get
    return self._create_connection()
  File "/home/newgraph/miniconda3/lib/python3.8/site-packages/sqlalchemy/pool/base.py", line 309, in _create_connection
    return _ConnectionRecord(self)
  File "/home/newgraph/miniconda3/lib/python3.8/site-packages/sqlalchemy/pool/base.py", line 440, in __init__
    self.__connect(first_connect_check=True)
  File "/home/newgraph/miniconda3/lib/python3.8/site-packages/sqlalchemy/pool/base.py", line 661, in __connect
    pool.logger.debug("Error on connect(): %s", e)
  File "/home/newgraph/miniconda3/lib/python3.8/site-packages/sqlalchemy/util/langhelpers.py", line 68, in __exit__
    compat.raise_(
  File "/home/newgraph/miniconda3/lib/python3.8/site-packages/sqlalchemy/util/compat.py", line 182, in raise_
    raise exception
  File "/home/newgraph/miniconda3/lib/python3.8/site-packages/sqlalchemy/pool/base.py", line 656, in __connect
    connection = pool._invoke_creator(self)
  File "/home/newgraph/miniconda3/lib/python3.8/site-packages/sqlalchemy/engine/strategies.py", line 114, in connect
    return dialect.connect(*cargs, **cparams)
  File "/home/newgraph/miniconda3/lib/python3.8/site-packages/sqlalchemy/engine/default.py", line 508, in connect
    return self.dbapi.connect(*cargs, **cparams)
  File "/home/newgraph/miniconda3/lib/python3.8/site-packages/psycopg2/__init__.py", line 127, in connect
    conn = _connect(dsn, connection_factory=connection_factory, **kwasync)
sqlalchemy.exc.OperationalError: (psycopg2.OperationalError) FATAL:  password authentication failed for user "newgraph"
FATAL:  password authentication failed for user "newgraph"

(Background on this error at: http://sqlalche.me/e/13/e3q8)
(base) newgraph@MSI:~$ ip addr
1: lo: <LOOPBACK,UP,LOWER_UP> mtu 65536 qdisc noqueue state UNKNOWN group default qlen 1000
    link/loopback 00:00:00:00:00:00 brd 00:00:00:00:00:00
    inet 127.0.0.1/8 scope host lo
       valid_lft forever preferred_lft forever
    inet6 ::1/128 scope host
       valid_lft forever preferred_lft forever
2: bond0: <BROADCAST,MULTICAST,MASTER> mtu 1500 qdisc noop state DOWN group default qlen 1000
    link/ether 6a:ee:2c:27:f1:c2 brd ff:ff:ff:ff:ff:ff
3: dummy0: <BROADCAST,NOARP> mtu 1500 qdisc noop state DOWN group default qlen 1000
    link/ether fe:34:2c:2f:c5:72 brd ff:ff:ff:ff:ff:ff
4: sit0@NONE: <NOARP> mtu 1480 qdisc noop state DOWN group default qlen 1000
    link/sit 0.0.0.0 brd 0.0.0.0
5: eth0: <BROADCAST,MULTICAST,UP,LOWER_UP> mtu 1500 qdisc mq state UP group default qlen 1000
    link/ether 00:15:5d:01:da:48 brd ff:ff:ff:ff:ff:ff
    inet 172.18.155.89/20 brd 172.18.159.255 scope global eth0
       valid_lft forever preferred_lft forever
    inet6 fe80::215:5dff:fe01:da48/64 scope link
       valid_lft forever preferred_lft forever
(base) newgraph@MSI:~$ bcdata bc2pg bc-airports --db_url postgresql://newgraph:newgraph101@host:5434/postgis_test
Traceback (most recent call last):
  File "/home/newgraph/miniconda3/lib/python3.8/site-packages/sqlalchemy/engine/base.py", line 2336, in _wrap_pool_connect
    return fn()
  File "/home/newgraph/miniconda3/lib/python3.8/site-packages/sqlalchemy/pool/base.py", line 364, in connect
    return _ConnectionFairy._checkout(self)
  File "/home/newgraph/miniconda3/lib/python3.8/site-packages/sqlalchemy/pool/base.py", line 778, in _checkout
    fairy = _ConnectionRecord.checkout(pool)
  File "/home/newgraph/miniconda3/lib/python3.8/site-packages/sqlalchemy/pool/base.py", line 495, in checkout
    rec = pool._do_get()
  File "/home/newgraph/miniconda3/lib/python3.8/site-packages/sqlalchemy/pool/impl.py", line 140, in _do_get
    self._dec_overflow()
  File "/home/newgraph/miniconda3/lib/python3.8/site-packages/sqlalchemy/util/langhelpers.py", line 68, in __exit__
    compat.raise_(
  File "/home/newgraph/miniconda3/lib/python3.8/site-packages/sqlalchemy/util/compat.py", line 182, in raise_
    raise exception
  File "/home/newgraph/miniconda3/lib/python3.8/site-packages/sqlalchemy/pool/impl.py", line 137, in _do_get
    return self._create_connection()
  File "/home/newgraph/miniconda3/lib/python3.8/site-packages/sqlalchemy/pool/base.py", line 309, in _create_connection
    return _ConnectionRecord(self)
  File "/home/newgraph/miniconda3/lib/python3.8/site-packages/sqlalchemy/pool/base.py", line 440, in __init__
    self.__connect(first_connect_check=True)
  File "/home/newgraph/miniconda3/lib/python3.8/site-packages/sqlalchemy/pool/base.py", line 661, in __connect
    pool.logger.debug("Error on connect(): %s", e)
  File "/home/newgraph/miniconda3/lib/python3.8/site-packages/sqlalchemy/util/langhelpers.py", line 68, in __exit__
    compat.raise_(
  File "/home/newgraph/miniconda3/lib/python3.8/site-packages/sqlalchemy/util/compat.py", line 182, in raise_
    raise exception
  File "/home/newgraph/miniconda3/lib/python3.8/site-packages/sqlalchemy/pool/base.py", line 656, in __connect
    connection = pool._invoke_creator(self)
  File "/home/newgraph/miniconda3/lib/python3.8/site-packages/sqlalchemy/engine/strategies.py", line 114, in connect
    return dialect.connect(*cargs, **cparams)
  File "/home/newgraph/miniconda3/lib/python3.8/site-packages/sqlalchemy/engine/default.py", line 508, in connect
    return self.dbapi.connect(*cargs, **cparams)
  File "/home/newgraph/miniconda3/lib/python3.8/site-packages/psycopg2/__init__.py", line 127, in connect
    conn = _connect(dsn, connection_factory=connection_factory, **kwasync)
psycopg2.OperationalError: could not connect to server: Connection timed out
        Is the server running on host "host" (172.18.144.1) and accepting
        TCP/IP connections on port 5434?


The above exception was the direct cause of the following exception:

Traceback (most recent call last):
  File "/home/newgraph/miniconda3/bin/bcdata", line 8, in <module>
    sys.exit(cli())
  File "/home/newgraph/miniconda3/lib/python3.8/site-packages/click/core.py", line 829, in __call__
    return self.main(*args, **kwargs)
  File "/home/newgraph/miniconda3/lib/python3.8/site-packages/click/core.py", line 782, in main
    rv = self.invoke(ctx)
  File "/home/newgraph/miniconda3/lib/python3.8/site-packages/click/core.py", line 1259, in invoke
    return _process_result(sub_ctx.command.invoke(sub_ctx))
  File "/home/newgraph/miniconda3/lib/python3.8/site-packages/click/core.py", line 1066, in invoke
    return ctx.invoke(self.callback, **ctx.params)
  File "/home/newgraph/miniconda3/lib/python3.8/site-packages/click/core.py", line 610, in invoke
    return callback(*args, **kwargs)
  File "/home/newgraph/miniconda3/lib/python3.8/site-packages/bcdata/cli.py", line 351, in bc2pg
    if schema not in conn.schemas:
  File "/home/newgraph/miniconda3/lib/python3.8/site-packages/pgdata/database.py", line 54, in schemas
    schemas = self.query(sql).fetchall()
  File "/home/newgraph/miniconda3/lib/python3.8/site-packages/pgdata/database.py", line 167, in query
    return self.engine.execute(sql, params)
  File "/home/newgraph/miniconda3/lib/python3.8/site-packages/sqlalchemy/engine/base.py", line 2234, in execute
    connection = self._contextual_connect(close_with_result=True)
  File "/home/newgraph/miniconda3/lib/python3.8/site-packages/sqlalchemy/engine/base.py", line 2302, in _contextual_connect
    self._wrap_pool_connect(self.pool.connect, None),
  File "/home/newgraph/miniconda3/lib/python3.8/site-packages/sqlalchemy/engine/base.py", line 2339, in _wrap_pool_connect
    Connection._handle_dbapi_exception_noconnection(
  File "/home/newgraph/miniconda3/lib/python3.8/site-packages/sqlalchemy/engine/base.py", line 1583, in _handle_dbapi_exception_noconnection
    util.raise_(
  File "/home/newgraph/miniconda3/lib/python3.8/site-packages/sqlalchemy/util/compat.py", line 182, in raise_
    raise exception
  File "/home/newgraph/miniconda3/lib/python3.8/site-packages/sqlalchemy/engine/base.py", line 2336, in _wrap_pool_connect
    return fn()
  File "/home/newgraph/miniconda3/lib/python3.8/site-packages/sqlalchemy/pool/base.py", line 364, in connect
    return _ConnectionFairy._checkout(self)
  File "/home/newgraph/miniconda3/lib/python3.8/site-packages/sqlalchemy/pool/base.py", line 778, in _checkout
    fairy = _ConnectionRecord.checkout(pool)
  File "/home/newgraph/miniconda3/lib/python3.8/site-packages/sqlalchemy/pool/base.py", line 495, in checkout
    rec = pool._do_get()
  File "/home/newgraph/miniconda3/lib/python3.8/site-packages/sqlalchemy/pool/impl.py", line 140, in _do_get
    self._dec_overflow()
  File "/home/newgraph/miniconda3/lib/python3.8/site-packages/sqlalchemy/util/langhelpers.py", line 68, in __exit__
    compat.raise_(
  File "/home/newgraph/miniconda3/lib/python3.8/site-packages/sqlalchemy/util/compat.py", line 182, in raise_
    raise exception
  File "/home/newgraph/miniconda3/lib/python3.8/site-packages/sqlalchemy/pool/impl.py", line 137, in _do_get
    return self._create_connection()
  File "/home/newgraph/miniconda3/lib/python3.8/site-packages/sqlalchemy/pool/base.py", line 309, in _create_connection
    return _ConnectionRecord(self)
  File "/home/newgraph/miniconda3/lib/python3.8/site-packages/sqlalchemy/pool/base.py", line 440, in __init__
    self.__connect(first_connect_check=True)
  File "/home/newgraph/miniconda3/lib/python3.8/site-packages/sqlalchemy/pool/base.py", line 661, in __connect
    pool.logger.debug("Error on connect(): %s", e)
  File "/home/newgraph/miniconda3/lib/python3.8/site-packages/sqlalchemy/util/langhelpers.py", line 68, in __exit__
    compat.raise_(
  File "/home/newgraph/miniconda3/lib/python3.8/site-packages/sqlalchemy/util/compat.py", line 182, in raise_
    raise exception
  File "/home/newgraph/miniconda3/lib/python3.8/site-packages/sqlalchemy/pool/base.py", line 656, in __connect
    connection = pool._invoke_creator(self)
  File "/home/newgraph/miniconda3/lib/python3.8/site-packages/sqlalchemy/engine/strategies.py", line 114, in connect
    return dialect.connect(*cargs, **cparams)
  File "/home/newgraph/miniconda3/lib/python3.8/site-packages/sqlalchemy/engine/default.py", line 508, in connect
    return self.dbapi.connect(*cargs, **cparams)
  File "/home/newgraph/miniconda3/lib/python3.8/site-packages/psycopg2/__init__.py", line 127, in connect
    conn = _connect(dsn, connection_factory=connection_factory, **kwasync)
sqlalchemy.exc.OperationalError: (psycopg2.OperationalError) could not connect to server: Connection timed out
        Is the server running on host "host" (172.18.144.1) and accepting
        TCP/IP connections on port 5434?

(Background on this error at: http://sqlalche.me/e/13/e3q8)
(base) newgraph@MSI:~$
       
       







List of commands

`\du` list db users and roles
`CREATE USER newgraph`
`GRANT ALL PRIVILEGES ON DATABASE postgis_test to newgraph;`
`\l` see databases and privileges




